Description


2015-03-26 18:16:38,833 [TezTaskRunner_attempt_1424502260528_1696_1_07_000000_0(container_222212222_1696_01_000220_sershe_20150326181607_188ab263-0a13-4528-b778-c803f378640d:1_Map 1_0_0)] ERROR org.apache.hadoop.hive.ql.exec.tez.TezProcessor: java.lang.RuntimeException: java.lang.AssertionError: Length is negative: -54
        at org.apache.hadoop.hive.ql.exec.tez.MapRecordSource.processRow(MapRecordSource.java:91)
        at org.apache.hadoop.hive.ql.exec.tez.MapRecordSource.pushRecord(MapRecordSource.java:68)
        at org.apache.hadoop.hive.ql.exec.tez.MapRecordProcessor.run(MapRecordProcessor.java:308)
        at org.apache.hadoop.hive.ql.exec.tez.TezProcessor.initializeAndRunProcessor(TezProcessor.java:148)
        at org.apache.hadoop.hive.ql.exec.tez.TezProcessor.run(TezProcessor.java:137)
        at org.apache.tez.runtime.LogicalIOProcessorRuntimeTask.run(LogicalIOProcessorRuntimeTask.java:330)
        at org.apache.tez.runtime.task.TezTaskRunner$TaskRunnerCallable$1.run(TezTaskRunner.java:179)
        at org.apache.tez.runtime.task.TezTaskRunner$TaskRunnerCallable$1.run(TezTaskRunner.java:171)
        at java.security.AccessController.doPrivileged(Native Method)
        at javax.security.auth.Subject.doAs(Subject.java:422)
        at org.apache.hadoop.security.UserGroupInformation.doAs(UserGroupInformation.java:1628)
        at org.apache.tez.runtime.task.TezTaskRunner$TaskRunnerCallable.callInternal(TezTaskRunner.java:171)
        at org.apache.tez.runtime.task.TezTaskRunner$TaskRunnerCallable.callInternal(TezTaskRunner.java:167)
        at org.apache.tez.common.CallableWithNdc.call(CallableWithNdc.java:36)
        at java.util.concurrent.FutureTask.run(FutureTask.java:266)
        at java.util.concurrent.ThreadPoolExecutor.runWorker(ThreadPoolExecutor.java:1142)
        at java.util.concurrent.ThreadPoolExecutor$Worker.run(ThreadPoolExecutor.java:617)
        at java.lang.Thread.run(Thread.java:745)
Caused by: java.lang.AssertionError: Length is negative: -54
        at org.apache.hadoop.hive.serde2.WriteBuffers$ByteSegmentRef.&amp;lt;init&amp;gt;(WriteBuffers.java:339)
        at org.apache.hadoop.hive.ql.exec.persistence.BytesBytesMultiHashMap.getValueRefs(BytesBytesMultiHashMap.java:270)
        at org.apache.hadoop.hive.ql.exec.persistence.MapJoinBytesTableContainer$ReusableRowContainer.setFromOutput(MapJoinBytesTableContainer.java:429)
        at org.apache.hadoop.hive.ql.exec.persistence.MapJoinBytesTableContainer$GetAdaptor.setFromVector(MapJoinBytesTableContainer.java:349)
        at org.apache.hadoop.hive.ql.exec.vector.VectorMapJoinOperator.setMapJoinKey(VectorMapJoinOperator.java:222)
        at org.apache.hadoop.hive.ql.exec.MapJoinOperator.process(MapJoinOperator.java:310)
        at org.apache.hadoop.hive.ql.exec.vector.VectorMapJoinOperator.process(VectorMapJoinOperator.java:252)
        at org.apache.hadoop.hive.ql.exec.Operator.forward(Operator.java:837)
        at org.apache.hadoop.hive.ql.exec.vector.VectorFilterOperator.process(VectorFilterOperator.java:114)
        at org.apache.hadoop.hive.ql.exec.Operator.forward(Operator.java:837)
        at org.apache.hadoop.hive.ql.exec.TableScanOperator.process(TableScanOperator.java:97)
        at org.apache.hadoop.hive.ql.exec.MapOperator$MapOpCtx.forward(MapOperator.java:163)        at org.apache.hadoop.hive.ql.exec.vector.VectorMapOperator.process(VectorMapOperator.java:45)
        at org.apache.hadoop.hive.ql.exec.tez.MapRecordSource.processRow(MapRecordSource.java:83)


Tasks do appear to pass on retries.


